

async function test() {
  ///////////////////////
  
  /////////////////////////
}
await test().catch((err) => {
  console.error("Error during test:", err);
});
console.log("End of test!");
